<?xml version="1.0" ?>
<sdf version="1.8">
    <model name='roboworks'>
      <link name='chassis'>
        <pose>0 0 0 0 0 0</pose>
        <inertial>
          <mass>100</mass>
          <inertia>
            <ixx>0.51286667</ixx>
            <ixy>0</ixy>
            <ixz>0</ixz>
            <iyy>1.28568542</iyy>
            <iyz>0</iyz>
            <izz>1.71688542</izz>
          </inertia>
        </inertial>
        <visual name='visual_chassis'>
          <pose>0 0 0 1.5707 0 0</pose>
          <geometry>
            <mesh>
              <uri>model://meshes/chassis.dae</uri>
            </mesh>
          </geometry>
          <material>
            <ambient>0.105882 0.058824 0.113725 1</ambient>
            <diffuse>0.427451 0.470588 0.541176 1</diffuse>
            <specular>0.333333 0.333333 0.521569 1</specular>
          </material>
        </visual>
        <collision name='collision_chassis'>
          <pose>0.17635 0 0 0 0 0</pose>
          <geometry>
            <box>
              <size>0.3865 0.238 0.07</size>
            </box>
          </geometry>
        </collision>
      </link>

      <link name='front_left_wheel'>
        <pose>0.3187 0.161 0 -1.5707 0 0</pose>
        <inertial>
          <mass>1</mass>
          <inertia>
            <ixx>1.18520833</ixx>
            <ixy>0</ixy>
            <ixz>0</ixz>
            <iyy>1.18520833</iyy>
            <iyz>0</iyz>
            <izz>0.78125</izz>
          </inertia>
        </inertial>
        <visual name='visual_front_left_wheel'>
          <geometry>
            <mesh>
              <uri>model://meshes/wheel.dae</uri>
            </mesh>
          </geometry>
          <material>
            <ambient>0.25 0.25 0.25 1</ambient>
            <diffuse>0.4 0.4 0.4 1</diffuse>
            <specular>0.774597 0.774597 0.774597 1</specular>
          </material>
        </visual>
        <collision name='collision_front_left_wheel'>
          <geometry>
            <cylinder>
              <length>0.04</length>
              <radius>0.0625</radius>
            </cylinder>
          </geometry>
          <surface>
            <friction>
              <ode>
                <mu>0.5</mu>
                <mu2>1.0</mu2>
                <fdir1>0 0 1</fdir1>
              </ode>
            </friction>
          </surface>
        </collision>
      </link>

      <link name='front_left_tire'>
        <pose>0.3187 0.161 0 -1.5707 0 0</pose>
        <visual name='visual_front_left_tire'>
          <geometry>
            <mesh>
              <uri>model://meshes/tire.dae</uri>
            </mesh>
          </geometry>
          <material>
            <ambient>0.02 0.02 0.02 1</ambient>
            <diffuse>0.01 0.01 0.01 1</diffuse>
            <specular>0.4 0.4 0.4 1</specular>
          </material>
        </visual>
      </link>

      <link name='front_right_wheel'>
        <pose>0.3187 -0.161 0 -1.5707 0 0</pose>
        <inertial>
          <mass>1</mass>
          <inertia>
            <ixx>1.18520833</ixx>
            <ixy>0</ixy>
            <ixz>0</ixz>
            <iyy>1.18520833</iyy>
            <iyz>0</iyz>
            <izz>0.78125</izz>
          </inertia>
        </inertial>
        <visual name='visual_front_right_wheel'>
          <pose>0 0 0 -3.1415 0 0</pose>
          <geometry>
            <mesh>
              <uri>model://meshes/wheel.dae</uri>
            </mesh>
          </geometry>
          <material>
            <ambient>0.25 0.25 0.25 1</ambient>
            <diffuse>0.4 0.4 0.4 1</diffuse>
            <specular>0.774597 0.774597 0.774597 1</specular>
          </material>
        </visual>
        <collision name='collision_front_right_wheel'>
          <geometry>
            <cylinder>
              <length>0.04</length>
              <radius>0.0625</radius>
            </cylinder>
          </geometry>
          <surface>
            <friction>
              <ode>
                <mu>0.5</mu>
                <mu2>1.0</mu2>
                <fdir1>0 0 1</fdir1>
              </ode>
            </friction>
          </surface>
        </collision>
      </link>

      <link name='front_right_tire'>
        <pose>0.3187 -0.161 0 1.5707 0 0</pose>
        <visual name='visual_front_right_tire'>
          <geometry>
            <mesh>
              <uri>model://meshes/tire.dae</uri>
            </mesh>
          </geometry>
          <material>
            <ambient>0.02 0.02 0.02 1</ambient>
            <diffuse>0.01 0.01 0.01 1</diffuse>
            <specular>0.4 0.4 0.4 1</specular>
          </material>
        </visual>
      </link>

      <link name='rear_left_wheel'>
        <pose>0 0.161 0 -1.5707 0 0</pose>
        <inertial>
          <mass>1</mass>
          <inertia>
            <ixx>1.18520833</ixx>
            <ixy>0</ixy>
            <ixz>0</ixz>
            <iyy>1.18520833</iyy>
            <iyz>0</iyz>
            <izz>0.78125</izz>
          </inertia>
        </inertial>
        <visual name='visual_rear_left_wheel'>
          <geometry>
            <mesh>
              <uri>model://meshes/wheel.dae</uri>
            </mesh>
          </geometry>
          <material>
            <ambient>0.25 0.25 0.25 1</ambient>
            <diffuse>0.4 0.4 0.4 1</diffuse>
            <specular>0.774597 0.774597 0.774597 1</specular>
          </material>
        </visual>
        <collision name='collision_rear_left_wheel'>
          <geometry>
            <cylinder>
              <length>0.04</length>
              <radius>0.0625</radius>
            </cylinder>
          </geometry>
          <surface>
            <friction>
              <ode>
                <mu>0.5</mu>
                <mu2>1.0</mu2>
                <fdir1>0 0 1</fdir1>
              </ode>
            </friction>
          </surface>
        </collision>
      </link>

      <link name='rear_left_tire'>
        <pose>0 0.161 0 -1.5707 0 0</pose>
        <visual name='visual_rear_left_tire'>
          <geometry>
            <mesh>
              <uri>model://meshes/tire.dae</uri>
            </mesh>
          </geometry>
          <material>
            <ambient>0.02 0.02 0.02 1</ambient>
            <diffuse>0.01 0.01 0.01 1</diffuse>
            <specular>0.4 0.4 0.4 1</specular>
          </material>
        </visual>
      </link>

      <link name='rear_right_wheel'>
        <pose>0 -0.161 0 -1.5707 0 0</pose>
        <inertial>
          <mass>1</mass>
          <inertia>
            <ixx>1.18520833</ixx>
            <ixy>0</ixy>
            <ixz>0</ixz>
            <iyy>1.18520833</iyy>
            <iyz>0</iyz>
            <izz>0.78125</izz>
          </inertia>
        </inertial>
        <visual name='visual_rear_right_wheel'>
          <pose>0 0 0 3.1415 0 0</pose>
          <geometry>
            <mesh>
              <uri>model://meshes/wheel.dae</uri>
            </mesh>
          </geometry>
          <material>
            <ambient>0.25 0.25 0.25 1</ambient>
            <diffuse>0.4 0.4 0.4 1</diffuse>
            <specular>0.774597 0.774597 0.774597 1</specular>
          </material>
        </visual>
        <collision name='collision_rear_right_wheel'>
          <geometry>
            <cylinder>
              <length>0.04</length>
              <radius>0.0625</radius>
            </cylinder>
          </geometry>
          <surface>
            <friction>
              <ode>
                <mu>0.5</mu>
                <mu2>1.0</mu2>
                <fdir1>0 0 1</fdir1>
              </ode>
            </friction>
          </surface>
        </collision>
      </link>

      <link name='rear_right_tire'>
        <pose>0 -0.161 0 1.5707 0 0</pose>
        <visual name='visual_rear_right_tire'>
          <geometry>
            <mesh>
              <uri>model://meshes/tire.dae</uri>
            </mesh>
          </geometry>
          <material>
            <ambient>0.02 0.02 0.02 1</ambient>
            <diffuse>0.01 0.01 0.01 1</diffuse>
            <specular>0.4 0.4 0.4 1</specular>
          </material>
        </visual>
      </link>

      <link name="front_left_wheel_steering_link">
        <pose>0.3187 0.131 0 0 0 0</pose>
        <visual name="front_left_wheel_steering_link_visual">
          <pose>0 0 0 0 0 0</pose>
          <geometry>
            <cylinder>
              <length>0.05</length>
              <radius>0.01</radius>
            </cylinder>
          </geometry>
          <material>
            <ambient>1 1 1</ambient>
            <diffuse>1 1 1</diffuse>
          </material>
        </visual>
      </link>

      <link name="front_right_wheel_steering_link">
        <pose>0.3187 -0.131 0 0 0 0</pose>
        <visual name="front_right_wheel_steering_link_visual">
          <geometry>
            <cylinder>
              <length>0.05</length>
              <radius>0.01</radius>
            </cylinder>
          </geometry>
          <material>
            <ambient>1 1 1</ambient>
            <diffuse>1 1 1</diffuse>
          </material>
        </visual>
      </link>

      <link name="lidar_link">
        <pose>0.25 0 0.094 0 0 0</pose>
        <inertial>
          <mass>0.1</mass>
          <inertia>
            <ixx>0.000166667</ixx>
            <iyy>0.000166667</iyy>
            <izz>0.000166667</izz>
          </inertia>
        </inertial>
        <collision name="collision">
          <geometry>
            <cylinder>
              <radius>0.035</radius>
              <length>0.039</length>
            </cylinder>
          </geometry>
        </collision>
        <visual name="visual">
          <geometry>
            <cylinder>
              <radius>0.035</radius>
              <length>0.039</length>
            </cylinder>
          </geometry>
        </visual>
        <sensor name='gpu_lidar' type='gpu_lidar'>
          <pose>0 0 0 0 0 0</pose>
          <topic>scan</topic>
          <ignition_frame_id>roboworks/lidar_link</ignition_frame_id>
          <update_rate>10</update_rate>
          <lidar>
            <scan>
              <horizontal>
                <samples>640</samples>
                <resolution>1</resolution>
                <min_angle>-1.396263</min_angle>
                <max_angle>1.396263</max_angle>
              </horizontal>
              <vertical>
                <samples>1</samples>
                <resolution>1</resolution>
                <min_angle>0.0</min_angle>
                <max_angle>0.0</max_angle>
              </vertical>
            </scan>
            <range>
              <min>0.08</min>
              <max>10.0</max>
              <resolution>0.01</resolution>
            </range>
          </lidar>
          <visualize>true</visualize>
        </sensor>
      </link>

      <joint name='lidar_joint' type='fixed'>
        <parent>chassis</parent>
        <child>lidar_link</child>
      </joint>

      <joint name="front_left_wheel_tire_joint" type="fixed">
        <child>front_left_tire</child>
        <parent>front_left_wheel</parent>
      </joint>

      <joint name="rear_left_wheel_tire_joint" type="fixed">
        <child>rear_left_tire</child>
        <parent>rear_left_wheel</parent>
      </joint>

      <joint name="front_right_wheel_tire_joint" type="fixed">
        <child>front_right_tire</child>
        <parent>front_right_wheel</parent>
      </joint>

      <joint name="rear_right_wheel_tire_joint" type="fixed">
        <child>rear_right_tire</child>
        <parent>rear_right_wheel</parent>
      </joint>

      <joint name="front_left_wheel_steering_joint" type="revolute">
        <child>front_left_wheel_steering_link</child>
        <parent>chassis</parent>
        <axis>
          <xyz>0 0 1</xyz>
          <limit>
            <lower>-0.6</lower>
            <upper>+0.6</upper>
            <velocity>1.0</velocity>
            <effort>25</effort>
          </limit>
          <use_parent_model_frame>1</use_parent_model_frame>
        </axis>
      </joint>

      <joint name="front_right_wheel_steering_joint" type="revolute">
        <parent>chassis</parent>
        <child>front_right_wheel_steering_link</child>
        <axis>
          <xyz>0 0 1</xyz>
          <limit>
            <lower>-0.6</lower>
            <upper>+0.6</upper>
            <velocity>1.0</velocity>
            <effort>25</effort>
          </limit>
        </axis>
      </joint>

      <joint name='front_left_wheel_joint' type='revolute'>
        <parent>front_left_wheel_steering_link</parent>
        <child>front_left_wheel</child>
        <axis>
          <xyz>0 0 1</xyz>
          <limit>
            <lower>-1.79769e+308</lower>
            <upper>1.79769e+308</upper>
          </limit>
        </axis>
      </joint>

      <joint name='front_right_wheel_joint' type='revolute'>
        <parent>front_right_wheel_steering_link</parent>
        <child>front_right_wheel</child>
        <axis>
          <xyz>0 0 1</xyz>
          <limit>
            <lower>-1.79769e+308</lower>
            <upper>1.79769e+308</upper>
          </limit>
        </axis>
      </joint>

      <joint name='rear_left_wheel_joint' type='revolute'>
        <parent>chassis</parent>
        <child>rear_left_wheel</child>
        <axis>
          <xyz>0 0 1</xyz>
          <limit>
            <lower>-1.79769e+308</lower>
            <upper>1.79769e+308</upper>
          </limit>
        </axis>
      </joint>

      <joint name='rear_right_wheel_joint' type='revolute'>
        <parent>chassis</parent>
        <child>rear_right_wheel</child>
        <axis>
          <xyz>0 0 1</xyz>
          <limit>
            <lower>-1.79769e+308</lower>
            <upper>1.79769e+308</upper>
          </limit>
        </axis>
      </joint>

      <plugin
        filename="ignition-gazebo-ackermann-steering-system"
        name="gz::sim::systems::AckermannSteering">
        <left_joint>front_left_wheel_joint</left_joint>
        <left_joint>rear_left_wheel_joint</left_joint>
        <right_joint>front_right_wheel_joint</right_joint>
        <right_joint>rear_right_wheel_joint</right_joint>
        <left_steering_joint>front_left_wheel_steering_joint</left_steering_joint>
        <right_steering_joint>front_right_wheel_steering_joint</right_steering_joint>
        <kingpin_width>0.262</kingpin_width>
        <steering_limit>0.4</steering_limit>
        <wheel_base>0.262</wheel_base>
        <wheel_separation>0.3187</wheel_separation>
        <wheel_radius>0.0625</wheel_radius>
        <odom_publish_frequency>1</odom_publish_frequency>
        <topic>model/roboworks/cmd_vel</topic>
        <min_velocity>-2</min_velocity>
        <max_velocity>2</max_velocity>
        <min_acceleration>-0.1</min_acceleration>
        <max_acceleration>0.1</max_acceleration>
      </plugin>
    </model>
</sdf>
